Workbook

Sheet 3 WEEK
B2: Project Name : | E2: SAMPLE | J2: Project No: | L2: XXXX | O2: From: | P2: 45320 | S2: To: | T2: =V6 -> 45340 | W2: 3 WEEK LOOK AHEAD SCHEDULE
M4: Project Supervisor | P4: FOREMAN
B5: M | C5: T | D5: W | E5: TH | F5: F | G5: S | H5: SU | I5: M | J5: T | K5: W | L5: TH | M5: F | N5: S | O5: SU | P5: M | Q5: T | R5: W | S5: TH | T5: F | U5: S | V5: SU | W5: Notes/Comments
B6: =P2 -> 45320 | C6: =B6+1 -> 45321 | D6: =C6+1 -> 45322 | E6: =D6+1 -> 45323 | F6: =E6+1 -> 45324 | G6: =F6+1 -> 45325 | H6: =G6+1 -> 45326 | I6: =H6+1 -> 45327 | J6: =I6+1 -> 45328 | ... V6: =U6+1 -> 45340
A7: ACTIVITY #1 | B7: \ | C7: \ | D7: \ | E7: \ | F7: \ | I7: \ | J7: \ | K7: \ | L7: \ | M7: \ | P7: \ | Q7: \ | R7: \ | S7: \ | T7: \ | W7: Notes
A8: CREW SIZE | B8: 6 | C8: 6 | D8: 6 | E8: 6 | F8: 6 | I8: 4 | J8: 4 | K8: 4 | L8: 4 | M8: 4 | P8: 4 | Q8: 4 | R8: 4 | S8: 4 | T8: 4
A9: ACTIVITY #2
A10: CREW SIZE
A11: ACTIVITY #3
A12: CREW SIZE
A13: ACTIVITY #4
A14: CREWSIZE
A15: ACTIVITY #5
A16: CREW SIZE
A17: ACTIVITY #6
A18: CREW SIZE
A19: ACTIVITY #7
A20: CREW SIZE
... A26: CREW SIZE
A27: Total Scheduled Crew Size | B27: =SUM(B8+B10+B12+B14+B16+B18+B20+B22+B24+B26) -> 6 | C27: =SUM(C8+C10+C12+C14+C16+C18+C20+C22+C24+C26) -> 6 | D27: =SUM(D8+D10+D12+D14+D16+D18+D20+D22+D24+D26) -> 6 | E27: =SUM(E8+E10+E12+E14+E16+E18+E20+E22+E24+E26) -> 6 | F27: =SUM(F8+F10+F12+F14+F16+F18+F20+F22+F24+F26) -> 6 | G27: =SUM(G8+G10+G12+G14+G16+G18+G20+G22+G24+G26) -> 0 | H27: =SUM(H8+H10+H12+H14+H16+H18+H20+H22+H24+H26) -> 0 | I27: =SUM(I8+I10+I12+I14+I16+I18+I20+I22+I24+I26) -> 4 | ... V27: =SUM(V8+V10+V12+V14+V16+V18+V20+V22+V24+V26) -> 0
A28: Total Actual Crew Size | B28: =SUM(#REF!+#REF!+#REF!+#REF!+#REF!+#REF!+#REF!+#REF!+#REF!) -> #REF! | C28: =SUM(#REF!+#REF!+#REF!+#REF!+#REF!+#REF!+#REF!+#REF!+#REF!) -> #REF! | D28: =SUM(#REF!+#REF!+#REF!+#REF!+#REF!+#REF!+#REF!+#REF!+#REF!) -> #REF! | E28: =SUM(#REF!+#REF!+#REF!+#REF!+#REF!+#REF!+#REF!+#REF!+#REF!) -> #REF! | F28: =SUM(#REF!+#REF!+#REF!+#REF!+#REF!+#REF!+#REF!+#REF!+#REF!) -> #REF! | G28: =SUM(#REF!+#REF!+#REF!+#REF!+#REF!+#REF!+#REF!+#REF!+#REF!) -> #REF! | H28: =SUM(#REF!+#REF!+#REF!+#REF!+#REF!+#REF!+#REF!+#REF!+#REF!) -> #REF! | I28: =SUM(#REF!+#REF!+#REF!+#REF!+#REF!+#REF!+#REF!+#REF!+#REF!) -> #REF! | ... V28: =SUM(#REF!+#REF!+#REF!+#REF!+#REF!+#REF!+#REF!+#REF!+#REF!) -> #REF!
A29: Journeyman
A30: Apprentices
A31: Manpower Total | B31: =SUM(B29+B30) -> 0 | C31: =SUM(C29+C30) -> 0 | D31: =SUM(D29+D30) -> 0 | E31: =SUM(E29+E30) -> 0 | F31: =SUM(F29+F30) -> 0 | G31: =SUM(G29+G30) -> 0 | H31: =SUM(H29+H30) -> 0 | I31: =SUM(I29+I30) -> 0 | ... V31: =SUM(V29+V30) -> 0

Sheet MATERIAL PLANNING
A1: MATERIAL LIST
A4: ACTIVITY | B4: MATERIAL | C4: QTY | D4: DATE NEEDED | E4: NOTES
A5: ='3 WEEK'!A7 -> ACTIVITY #1
A6: 1
A7: 2
A8: 3
A9: 4
A10: 5
A11: ='3 WEEK'!A9 -> ACTIVITY #2
A12: 1
A13: 2
A14: 3
A15: 4
A16: 5
A17: ='3 WEEK'!A11 -> ACTIVITY #3
A18: 1
A19: 2
A20: 3
A21: 4
A22: 5
A23: ='3 WEEK'!A13 -> ACTIVITY #4
A24: 1
A25: 2
A26: 3
A27: 4
A28: 5
A29: ='3 WEEK'!A15 -> ACTIVITY #5
A30: 1
A31: 2
A32: 3
A33: 4
A34: 5
A35: ='3 WEEK'!A17 -> ACTIVITY #6
A36: 1
A37: 2
A38: 3
A39: 4
A40: 5
A41: ='3 WEEK'!A19 -> ACTIVITY #7
A42: 1
...

Sheet EQUIP-TOOL PLANNING
A1: EQUIPMENT/TOOL LIST
A4: ACTIVITY | B4: EQUIPMENT/TOOLS | C4: QTY | D4: DATE NEEDED | E4: NOTES
A5: ='3 WEEK'!A7 -> ACTIVITY #1
A6: 1
A7: 2
A8: 3
A9: 4
A10: 5
A11: ='3 WEEK'!A9 -> ACTIVITY #2
A12: 1
A13: 2
A14: 3
A15: 4
A16: 5
A17: ='3 WEEK'!A11 -> ACTIVITY #3
A18: 1
A19: 2
A20: 3
A21: 4
A22: 5
A23: ='3 WEEK'!A13 -> ACTIVITY #4
A24: 1
A25: 2
A26: 3
A27: 4
A28: 5
A29: ='3 WEEK'!A15 -> ACTIVITY #5
A30: 1
A31: 2
A32: 3
A33: 4
A34: 5
A35: ='3 WEEK'!A17 -> ACTIVITY #6
A36: 1
A37: 2
A38: 3
A39: 4
A40: 5
A41: ='3 WEEK'!A19 -> ACTIVITY #7
A42: 1
...

Sheet BACKUP PLAN
A1: BACKUP ACTIVITIES
A4: PLANNED ACTIVITY | B4: BACKUP PLAN ACTIVITY | C4: MATERIAL LIST | D4: QTY | E4: DATE NEEDED | F4: EQUIPMENT / TOOLS | G4: QTY | H4: DATE NEEDED | I4: NOTES
A5: ='3 WEEK'!A7 -> ACTIVITY #1
A6: 1 | B6: BACKUP PLAN 1 | C6: MATERIAL A1 | F6: EQUIPMENT A1
C7: MATERIAL A2 | F7: EQUIPMENT A2
C8: MATERIAL A3 | F8: EQUIPMENT A3
A9: 2 | B9: BACKUP PLAN 2 | C9: MATERIAL B1 | F9: EQUIPMENT B1
C10: MATERIAL B2 | F10: EQUIPMENT B2
C11: MATERIAL B3 | F11: EQUIPMENT B3
A12: 3 | B12: BACKUP PLAN 3 | C12: MATERIAL C1 | F12: EQUIPMENT C1
C13: MATERIAL C2 | F13: EQUIPMENT C2
C14: MATERIAL C3 | F14: EQUIPMENT C3
A15: ='3 WEEK'!A9 -> ACTIVITY #2
A16: 1
A19: 2
A22: 3
A25: ='3 WEEK'!A11 -> ACTIVITY #3
A26: 1
A29: 2
A32: 3
A35: ='3 WEEK'!A13 -> ACTIVITY #4
A36: 1
A39: 2
A42: 3
A45: ='3 WEEK'!A15 -> ACTIVITY #5
A46: 1
A49: 2
A52: 3
A55: ='3 WEEK'!A17 -> ACTIVITY #6
A56: 1
A59: 2
A62: 3
A65: ='3 WEEK'!A19 -> ACTIVITY #7
A66: 1
A69: 2
A72: 3
A75: ='3 WEEK'!A21 -> ACTIVITY #8
A76: 1
A79: 2
A82: 3
...

Sheet LABOR CALCULATOR
A1: LABOR CALCULATOR
F2: *DO NOT TYPE IN GREEN CELLS
A4: MATERIAL - PER EA. (E) (DEVICES, DISC, GEAR, FIXTURES, ETC) | B4: QTY | C4: EST RATE | D4: EST HRS
D6: =B6*C6 -> 0
D7: =B7*C7 -> 0
D8: =B8*C8 -> 0
D9: =B9*C9 -> 0
D10: =B10*C10 -> 0
D11: =B11*C11 -> 0
D12: =B12*C12 -> 0
D13: =B13*C13 -> 0
D14: =B14*C14 -> 0
D15: =B15*C15 -> 0
A16: SUBTOTAL | D16: =SUM(D6:D15) -> 0
A18: MATERIAL - PER HUNDRED (C) (CONDUIT, TRAY, ETC) | B18: QTY | C18: EST RATE | D18: EST HRS
D20: =(B20*C20)/100 -> 0
D21: =(B21*C21)/100 -> 0
D22: =(B22*C22)/100 -> 0
D23: =(B23*C23)/100 -> 0
D24: =(B24*C24)/100 -> 0
D25: =(B25*C25)/100 -> 0
D26: =(B26*C26)/100 -> 0
D27: =(B27*C27)/100 -> 0
D28: =(B28*C28)/100 -> 0
D29: =(B29*C29)/100 -> 0
D30: =(B30*C30)/100 -> 0
D31: =(B31*C31)/100 -> 0
A32: SUBTOTAL | D32: =SUM(D20:D31) -> 0
A34: MATERIAL - PER THOUSAND (M) (WIRE/CABLE ETC) | B34: QTY | C34: EST RATE | D34: EST HRS
D36: =(B36*C36)/1000 -> 0
D37: =(B37*C37)/1000 -> 0
D38: =(B38*C38)/1000 -> 0
D39: =(B39*C39)/1000 -> 0
D40: =(B40*C40)/1000 -> 0
D41: =(B41*C41)/1000 -> 0
D42: =(B42*C42)/1000 -> 0
D43: =(B43*C43)/1000 -> 0
D44: =(B44*C44)/1000 -> 0
D45: =(B45*C45)/1000 -> 0
D46: =(B46*C46)/1000 -> 0
...
